<?xml version="1.0" ?>
<!-- =================================================================================== -->
<!-- |    This document was autogenerated by xacro from robot.xacro                    | -->
<!-- |    EDITING THIS FILE BY HAND IS NOT RECOMMENDED                                 | -->
<!-- =================================================================================== -->
<robot name="simple_bot" xmlns:xacro="http://www.ros.org/wiki/xacro">
  <gazebo reference="base_link">
    <mu1 value="1.0"/>
    <mu2 value="1.0"/>
    <kp value="10000.0"/>
    <kd value="1.0"/>
    <fdir1 value="1 0 0"/>
    <turnGravityOff>false</turnGravityOff>
  </gazebo>
  <gazebo reference="arm_link">
    <mu1 value="1.0"/>
    <mu2 value="1.0"/>
    <kp value="10000.0"/>
    <kd value="1.0"/>
    <fdir1 value="1 0 0"/>
    <turnGravityOff>false</turnGravityOff>
  </gazebo>
  <gazebo reference="end_effector">
    <mu1 value="1.0"/>
    <mu2 value="1.0"/>
    <kp value="10000.0"/>
    <kd value="1.0"/>
    <fdir1 value="1 0 0"/>
    <turnGravityOff>false</turnGravityOff>
  </gazebo>
  <gazebo reference="base_to_arm_joint">
    <provideFeedback>true</provideFeedback>
    <turnGravityOff>false</turnGravityOff>
  </gazebo>
  <gazebo reference="ft_sensor_joint">
    <provideFeedback>true</provideFeedback>
    <turnGravityOff>false</turnGravityOff>
  </gazebo>
  <gazebo>
    <plugin filename="libgazebo_ros_ft_sensor.so" name="ft_sensor">
      <updateRate>100.0</updateRate>
      <topicName>ftsensor/raw</topicName>
      <jointName>ft_sensor_joint</jointName>
      <gaussianNoise>0.0</gaussianNoise>
    </plugin>
  </gazebo>
  <gazebo>
    <plugin filename="libgazebo_ros_control.so" name="gazebo_ros_control">
      <robotNamespace>/simple_bot</robotNamespace>
    </plugin>
  </gazebo>
  <link name="world"/>
  <joint name="world_joint" type="fixed">
    <parent link="world"/>
    <child link="base_link"/>
  </joint>
  <link name="base_link">
    <collision>
      <origin rpy="0 0 0" xyz="0 0 0.5"/>
      <geometry>
        <box size="0.1 0.1 1.0"/>
      </geometry>
    </collision>
    <visual>
      <origin rpy="0 0 0" xyz="0 0 0.5"/>
      <geometry>
        <box size="0.1 0.1 1.0"/>
      </geometry>
    </visual>
    <inertial>
      <origin rpy="0 0 0" xyz="0 0 0.5"/>
      <mass value="1.0"/>
      <inertia ixx="0.0841666666667" ixy="0.0" ixz="0.0" iyy="0.0841666666667" iyz="0.0" izz="0.0175"/>
    </inertial>
  </link>
  <joint name="base_to_chest_joint" type="prismatic">
    <parent link="base_link"/>
    <child link="arm_link"/>
    <limit effort="1000.0" lower="-0.5" upper="0.5" velocity="0.5"/>
    <origin rpy="0 0 0" xyz="0 0 1.05"/>
  </joint>
  <link name="arm_link">
    <collision>
      <origin rpy="0 0 0" xyz="0 0 0"/>
      <geometry>
        <box size="1.0 0.1 0.1"/>
      </geometry>
    </collision>
    <visual>
      <origin rpy="0 0 0" xyz="0 0 0"/>
      <geometry>
        <box size="1.0 0.1 0.1"/>
      </geometry>
    </visual>
    <inertial>
      <origin rpy="0 0 0" xyz="0 0 0"/>
      <mass value="1.0"/>
      <inertia ixx="0.0841666666667" ixy="0.0" ixz="0.0" iyy="0.0841666666667" iyz="0.0" izz="0.0175"/>
    </inertial>
  </link>
  <joint name="ft_sensor_joint" type="revolute">
    <parent link="arm_link"/>
    <child link="end_effector"/>
    <origin rpy="0 0 0" xyz="0.5 0 0"/>
    <axis xyz="0 0 1"/>
    <limit effort="0.0" lower="0" upper="0" velocity="0.0"/>
  </joint>
  <link name="end_effector">
    <collision>
      <origin rpy="0 0 0" xyz="0.05 0 0"/>
      <geometry>
        <box size="0.1 0.1 0.1"/>
      </geometry>
    </collision>
    <visual>
      <origin rpy="0 0 0" xyz="0.05 0 0"/>
      <geometry>
        <box size="0.1 0.1 0.1"/>
      </geometry>
    </visual>
    <inertial>
      <origin rpy="0 0 0" xyz="0 0 0"/>
      <mass value="1.0"/>
      <inertia ixx="0.00166666666667" ixy="0.0" ixz="0.0" iyy="0.00166666666667" iyz="0.0" izz="0.0175"/>
    </inertial>
  </link>
</robot>

